[2025-08-08T15:20:27.192-0300] {local_task_job_runner.py:120} INFO - ::group::Pre task execution logs
[2025-08-08T15:20:27.202-0300] {taskinstance.py:2076} INFO - Dependencies all met for dep_context=non-requeueable deps ti=<TaskInstance: exportar_bq_para_gcs_csv.exportar_tabela_bq_gcs scheduled__2025-08-07T10:00:00+00:00 [queued]>
[2025-08-08T15:20:27.206-0300] {taskinstance.py:2076} INFO - Dependencies all met for dep_context=requeueable deps ti=<TaskInstance: exportar_bq_para_gcs_csv.exportar_tabela_bq_gcs scheduled__2025-08-07T10:00:00+00:00 [queued]>
[2025-08-08T15:20:27.207-0300] {taskinstance.py:2306} INFO - Starting attempt 1 of 1
[2025-08-08T15:20:27.213-0300] {taskinstance.py:2330} INFO - Executing <Task(BigQueryToGCSOperator): exportar_tabela_bq_gcs> on 2025-08-07 10:00:00+00:00
[2025-08-08T15:20:27.219-0300] {standard_task_runner.py:63} INFO - Started process 219 to run task
[2025-08-08T15:20:27.220-0300] {standard_task_runner.py:90} INFO - Running: ['***', 'tasks', 'run', 'exportar_bq_para_gcs_csv', 'exportar_tabela_bq_gcs', 'scheduled__2025-08-07T10:00:00+00:00', '--job-id', '121', '--raw', '--subdir', 'DAGS_FOLDER/notas_ordem.py', '--cfg-path', '/tmp/tmpnoo66yse']
[2025-08-08T15:20:27.221-0300] {standard_task_runner.py:91} INFO - Job 121: Subtask exportar_tabela_bq_gcs
[2025-08-08T15:20:27.247-0300] {task_command.py:426} INFO - Running <TaskInstance: exportar_bq_para_gcs_csv.exportar_tabela_bq_gcs scheduled__2025-08-07T10:00:00+00:00 [running]> on host be375a341e67
[2025-08-08T15:20:27.293-0300] {taskinstance.py:2648} INFO - Exporting env vars: AIRFLOW_CTX_DAG_OWNER='***' AIRFLOW_CTX_DAG_ID='exportar_bq_para_gcs_csv' AIRFLOW_CTX_TASK_ID='exportar_tabela_bq_gcs' AIRFLOW_CTX_EXECUTION_DATE='2025-08-07T10:00:00+00:00' AIRFLOW_CTX_TRY_NUMBER='1' AIRFLOW_CTX_DAG_RUN_ID='scheduled__2025-08-07T10:00:00+00:00'
[2025-08-08T15:20:27.294-0300] {taskinstance.py:430} INFO - ::endgroup::
[2025-08-08T15:20:27.300-0300] {bigquery_to_gcs.py:201} INFO - Executing extract of sz-00022-ws.PLAMI.TMP_NOTAS_ORDENS into: ['gs://***_vps/nota_ordem.csv']
[2025-08-08T15:20:27.301-0300] {connection.py:513} ERROR - Unable to retrieve connection from secrets backend (EnvironmentVariablesBackend). Checking subsequent secrets backend.
Traceback (most recent call last):
  File "/home/airflow/.local/lib/python3.11/site-packages/airflow/models/connection.py", line 508, in get_connection_from_secrets
    conn = secrets_backend.get_connection(conn_id=conn_id)
           ^^^^^^^^^^^^^^^^^^^^^^^^^^^^^^^^^^^^^^^^^^^^^^^
  File "/home/airflow/.local/lib/python3.11/site-packages/airflow/secrets/base_secrets.py", line 116, in get_connection
    return self.deserialize_connection(conn_id=conn_id, value=value)
           ^^^^^^^^^^^^^^^^^^^^^^^^^^^^^^^^^^^^^^^^^^^^^^^^^^^^^^^^^
  File "/home/airflow/.local/lib/python3.11/site-packages/airflow/secrets/base_secrets.py", line 68, in deserialize_connection
    return Connection.from_json(conn_id=conn_id, value=value)
           ^^^^^^^^^^^^^^^^^^^^^^^^^^^^^^^^^^^^^^^^^^^^^^^^^^
  File "/home/airflow/.local/lib/python3.11/site-packages/airflow/models/connection.py", line 564, in from_json
    return Connection(conn_id=conn_id, **kwargs)
           ^^^^^^^^^^^^^^^^^^^^^^^^^^^^^^^^^^^^^
TypeError: __init__() got an unexpected keyword argument 'extra__google_cloud_platform__project'
[2025-08-08T15:20:27.306-0300] {connection.py:274} WARNING - Connection schemes (type: google_cloud_platform) shall not contain '_' according to RFC3986.
[2025-08-08T15:20:27.306-0300] {base.py:84} INFO - Using connection ID 'google_cloud_default' for task execution.
[2025-08-08T15:20:27.306-0300] {credentials_provider.py:353} INFO - Getting connection using `google.auth.default()` since no explicit credentials are provided.
[2025-08-08T15:20:27.342-0300] {bigquery_to_gcs.py:224} INFO - Executing: {'extract': {'sourceTable': {'projectId': 'sz-00022-ws', 'datasetId': 'PLAMI', 'tableId': 'TMP_NOTAS_ORDENS'}, 'compression': 'NONE', 'destinationUris': ['gs://***_vps/nota_ordem.csv'], 'destinationFormat': 'CSV', 'fieldDelimiter': '\x1f', 'printHeader': True}}
[2025-08-08T15:20:27.342-0300] {bigquery.py:1660} INFO - Inserting job ***_exportar_bq_para_gcs_csv_exportar_tabela_bq_gcs_2025_08_07T10_00_00_00_00_25a7e0156089b94962a331960db9c41f
[2025-08-08T15:20:29.388-0300] {taskinstance.py:441} INFO - ::group::Post task execution logs
[2025-08-08T15:20:29.389-0300] {taskinstance.py:2905} ERROR - Task failed with exception
Traceback (most recent call last):
  File "/home/airflow/.local/lib/python3.11/site-packages/airflow/models/taskinstance.py", line 465, in _execute_task
    result = _execute_callable(context=context, **execute_callable_kwargs)
             ^^^^^^^^^^^^^^^^^^^^^^^^^^^^^^^^^^^^^^^^^^^^^^^^^^^^^^^^^^^^^
  File "/home/airflow/.local/lib/python3.11/site-packages/airflow/models/taskinstance.py", line 432, in _execute_callable
    return execute_callable(context=context, **execute_callable_kwargs)
           ^^^^^^^^^^^^^^^^^^^^^^^^^^^^^^^^^^^^^^^^^^^^^^^^^^^^^^^^^^^^
  File "/home/airflow/.local/lib/python3.11/site-packages/airflow/models/baseoperator.py", line 400, in wrapper
    return func(self, *args, **kwargs)
           ^^^^^^^^^^^^^^^^^^^^^^^^^^^
  File "/home/airflow/.local/lib/python3.11/site-packages/airflow/providers/google/cloud/transfers/bigquery_to_gcs.py", line 230, in execute
    job = hook.get_job(
          ^^^^^^^^^^^^^
  File "/home/airflow/.local/lib/python3.11/site-packages/airflow/providers/google/common/hooks/base_google.py", line 486, in inner_wrapper
    return func(self, *args, **kwargs)
           ^^^^^^^^^^^^^^^^^^^^^^^^^^^
  File "/home/airflow/.local/lib/python3.11/site-packages/airflow/providers/google/cloud/hooks/bigquery.py", line 1593, in get_job
    job = client.get_job(job_id=job_id, project=project_id, location=location)
          ^^^^^^^^^^^^^^^^^^^^^^^^^^^^^^^^^^^^^^^^^^^^^^^^^^^^^^^^^^^^^^^^^^^^
  File "/home/airflow/.local/lib/python3.11/site-packages/google/cloud/bigquery/client.py", line 2192, in get_job
    resource = self._call_api(
               ^^^^^^^^^^^^^^^
  File "/home/airflow/.local/lib/python3.11/site-packages/google/cloud/bigquery/client.py", line 831, in _call_api
    return call()
           ^^^^^^
  File "/home/airflow/.local/lib/python3.11/site-packages/google/api_core/retry/retry_unary.py", line 293, in retry_wrapped_func
    return retry_target(
           ^^^^^^^^^^^^^
  File "/home/airflow/.local/lib/python3.11/site-packages/google/api_core/retry/retry_unary.py", line 153, in retry_target
    _retry_error_helper(
  File "/home/airflow/.local/lib/python3.11/site-packages/google/api_core/retry/retry_base.py", line 212, in _retry_error_helper
    raise final_exc from source_exc
  File "/home/airflow/.local/lib/python3.11/site-packages/google/api_core/retry/retry_unary.py", line 144, in retry_target
    result = target()
             ^^^^^^^^
  File "/home/airflow/.local/lib/python3.11/site-packages/google/cloud/_http/__init__.py", line 494, in api_request
    raise exceptions.from_http_response(response)
google.api_core.exceptions.NotFound: 404 GET https://bigquery.googleapis.com/bigquery/v2/projects/sz-00022-ws/jobs/airflow_exportar_bq_para_gcs_csv_exportar_tabela_bq_gcs_2025_08_07T10_00_00_00_00_25a7e0156089b94962a331960db9c41f?projection=full&prettyPrint=false: Not found: Job sz-00022-ws:airflow_exportar_bq_para_gcs_csv_exportar_tabela_bq_gcs_2025_08_07T10_00_00_00_00_25a7e0156089b94962a331960db9c41f
[2025-08-08T15:20:29.405-0300] {taskinstance.py:1206} INFO - Marking task as FAILED. dag_id=exportar_bq_para_gcs_csv, task_id=exportar_tabela_bq_gcs, run_id=scheduled__2025-08-07T10:00:00+00:00, execution_date=20250807T100000, start_date=20250808T182027, end_date=20250808T182029
[2025-08-08T15:20:29.423-0300] {standard_task_runner.py:110} ERROR - Failed to execute job 121 for task exportar_tabela_bq_gcs (404 GET https://bigquery.googleapis.com/bigquery/v2/projects/sz-00022-ws/jobs/airflow_exportar_bq_para_gcs_csv_exportar_tabela_bq_gcs_2025_08_07T10_00_00_00_00_25a7e0156089b94962a331960db9c41f?projection=full&prettyPrint=false: Not found: Job sz-00022-ws:airflow_exportar_bq_para_gcs_csv_exportar_tabela_bq_gcs_2025_08_07T10_00_00_00_00_25a7e0156089b94962a331960db9c41f; 219)
[2025-08-08T15:20:29.439-0300] {local_task_job_runner.py:240} INFO - Task exited with return code 1
[2025-08-08T15:20:29.463-0300] {taskinstance.py:3498} INFO - 0 downstream tasks scheduled from follow-on schedule check
[2025-08-08T15:20:29.465-0300] {local_task_job_runner.py:222} INFO - ::endgroup::
[2025-08-08T15:38:14.085-0300] {local_task_job_runner.py:120} INFO - ::group::Pre task execution logs
[2025-08-08T15:38:14.096-0300] {taskinstance.py:2076} INFO - Dependencies all met for dep_context=non-requeueable deps ti=<TaskInstance: exportar_bq_para_gcs_csv.exportar_tabela_bq_gcs scheduled__2025-08-07T10:00:00+00:00 [queued]>
[2025-08-08T15:38:14.101-0300] {taskinstance.py:2076} INFO - Dependencies all met for dep_context=requeueable deps ti=<TaskInstance: exportar_bq_para_gcs_csv.exportar_tabela_bq_gcs scheduled__2025-08-07T10:00:00+00:00 [queued]>
[2025-08-08T15:38:14.101-0300] {taskinstance.py:2306} INFO - Starting attempt 1 of 1
[2025-08-08T15:38:14.108-0300] {taskinstance.py:2330} INFO - Executing <Task(BigQueryToGCSOperator): exportar_tabela_bq_gcs> on 2025-08-07 10:00:00+00:00
[2025-08-08T15:38:14.112-0300] {standard_task_runner.py:63} INFO - Started process 251 to run task
[2025-08-08T15:38:14.114-0300] {standard_task_runner.py:90} INFO - Running: ['***', 'tasks', 'run', 'exportar_bq_para_gcs_csv', 'exportar_tabela_bq_gcs', 'scheduled__2025-08-07T10:00:00+00:00', '--job-id', '131', '--raw', '--subdir', 'DAGS_FOLDER/notas_ordem.py', '--cfg-path', '/tmp/tmphdqebym3']
[2025-08-08T15:38:14.115-0300] {standard_task_runner.py:91} INFO - Job 131: Subtask exportar_tabela_bq_gcs
[2025-08-08T15:38:14.145-0300] {task_command.py:426} INFO - Running <TaskInstance: exportar_bq_para_gcs_csv.exportar_tabela_bq_gcs scheduled__2025-08-07T10:00:00+00:00 [running]> on host b5a2a68d2496
[2025-08-08T15:38:14.199-0300] {taskinstance.py:2648} INFO - Exporting env vars: AIRFLOW_CTX_DAG_OWNER='***' AIRFLOW_CTX_DAG_ID='exportar_bq_para_gcs_csv' AIRFLOW_CTX_TASK_ID='exportar_tabela_bq_gcs' AIRFLOW_CTX_EXECUTION_DATE='2025-08-07T10:00:00+00:00' AIRFLOW_CTX_TRY_NUMBER='1' AIRFLOW_CTX_DAG_RUN_ID='scheduled__2025-08-07T10:00:00+00:00'
[2025-08-08T15:38:14.200-0300] {taskinstance.py:430} INFO - ::endgroup::
[2025-08-08T15:38:14.207-0300] {bigquery_to_gcs.py:201} INFO - Executing extract of sz-00022-ws.PLAMI.TMP_NOTAS_ORDENS into: ['gs://***_vps/nota_ordem.csv']
[2025-08-08T15:38:14.208-0300] {crypto.py:82} WARNING - empty cryptography key - values will not be stored encrypted.
[2025-08-08T15:38:14.208-0300] {connection.py:274} WARNING - Connection schemes (type: google_cloud_platform) shall not contain '_' according to RFC3986.
[2025-08-08T15:38:14.208-0300] {base.py:84} INFO - Using connection ID 'google_cloud_default' for task execution.
[2025-08-08T15:38:14.244-0300] {bigquery_to_gcs.py:224} INFO - Executing: {'extract': {'sourceTable': {'projectId': 'sz-00022-ws', 'datasetId': 'PLAMI', 'tableId': 'TMP_NOTAS_ORDENS'}, 'compression': 'NONE', 'destinationUris': ['gs://***_vps/nota_ordem.csv'], 'destinationFormat': 'CSV', 'fieldDelimiter': '\x1f', 'printHeader': True}}
[2025-08-08T15:38:14.245-0300] {bigquery.py:1660} INFO - Inserting job ***_exportar_bq_para_gcs_csv_exportar_tabela_bq_gcs_2025_08_07T10_00_00_00_00_25a7e0156089b94962a331960db9c41f
[2025-08-08T15:38:15.790-0300] {taskinstance.py:441} INFO - ::group::Post task execution logs
[2025-08-08T15:38:15.803-0300] {taskinstance.py:2905} ERROR - Task failed with exception
Traceback (most recent call last):
  File "/home/airflow/.local/lib/python3.11/site-packages/airflow/providers/google/cloud/transfers/bigquery_to_gcs.py", line 225, in execute
    job: BigQueryJob | UnknownJob = self._submit_job(
                                    ^^^^^^^^^^^^^^^^^
  File "/home/airflow/.local/lib/python3.11/site-packages/airflow/providers/google/cloud/transfers/bigquery_to_gcs.py", line 190, in _submit_job
    return hook.insert_job(
           ^^^^^^^^^^^^^^^^
  File "/home/airflow/.local/lib/python3.11/site-packages/airflow/providers/google/common/hooks/base_google.py", line 486, in inner_wrapper
    return func(self, *args, **kwargs)
           ^^^^^^^^^^^^^^^^^^^^^^^^^^^
  File "/home/airflow/.local/lib/python3.11/site-packages/airflow/providers/google/cloud/hooks/bigquery.py", line 1666, in insert_job
    job_api_repr.result(timeout=timeout, retry=retry)
  File "/home/airflow/.local/lib/python3.11/site-packages/google/cloud/bigquery/job/base.py", line 968, in result
    self._begin(retry=retry, timeout=timeout)
  File "/home/airflow/.local/lib/python3.11/site-packages/google/cloud/bigquery/job/base.py", line 740, in _begin
    api_response = client._call_api(
                   ^^^^^^^^^^^^^^^^^
  File "/home/airflow/.local/lib/python3.11/site-packages/google/cloud/bigquery/client.py", line 831, in _call_api
    return call()
           ^^^^^^
  File "/home/airflow/.local/lib/python3.11/site-packages/google/api_core/retry/retry_unary.py", line 293, in retry_wrapped_func
    return retry_target(
           ^^^^^^^^^^^^^
  File "/home/airflow/.local/lib/python3.11/site-packages/google/api_core/retry/retry_unary.py", line 153, in retry_target
    _retry_error_helper(
  File "/home/airflow/.local/lib/python3.11/site-packages/google/api_core/retry/retry_base.py", line 212, in _retry_error_helper
    raise final_exc from source_exc
  File "/home/airflow/.local/lib/python3.11/site-packages/google/api_core/retry/retry_unary.py", line 144, in retry_target
    result = target()
             ^^^^^^^^
  File "/home/airflow/.local/lib/python3.11/site-packages/google/cloud/_http/__init__.py", line 494, in api_request
    raise exceptions.from_http_response(response)
google.api_core.exceptions.Conflict: 409 POST https://bigquery.googleapis.com/bigquery/v2/projects/sz-00022-ws/jobs?prettyPrint=false: Already Exists: Job sz-00022-ws:southamerica-east1.airflow_exportar_bq_para_gcs_csv_exportar_tabela_bq_gcs_2025_08_07T10_00_00_00_00_25a7e0156089b94962a331960db9c41f

During handling of the above exception, another exception occurred:

Traceback (most recent call last):
  File "/home/airflow/.local/lib/python3.11/site-packages/airflow/models/taskinstance.py", line 465, in _execute_task
    result = _execute_callable(context=context, **execute_callable_kwargs)
             ^^^^^^^^^^^^^^^^^^^^^^^^^^^^^^^^^^^^^^^^^^^^^^^^^^^^^^^^^^^^^
  File "/home/airflow/.local/lib/python3.11/site-packages/airflow/models/taskinstance.py", line 432, in _execute_callable
    return execute_callable(context=context, **execute_callable_kwargs)
           ^^^^^^^^^^^^^^^^^^^^^^^^^^^^^^^^^^^^^^^^^^^^^^^^^^^^^^^^^^^^
  File "/home/airflow/.local/lib/python3.11/site-packages/airflow/models/baseoperator.py", line 400, in wrapper
    return func(self, *args, **kwargs)
           ^^^^^^^^^^^^^^^^^^^^^^^^^^^
  File "/home/airflow/.local/lib/python3.11/site-packages/airflow/providers/google/cloud/transfers/bigquery_to_gcs.py", line 241, in execute
    raise AirflowException(
airflow.exceptions.AirflowException: Job with id: ***_exportar_bq_para_gcs_csv_exportar_tabela_bq_gcs_2025_08_07T10_00_00_00_00_25a7e0156089b94962a331960db9c41f already exists and is in DONE state. If you want to force rerun it consider setting `force_rerun=True`.Or, if you want to reattach in this scenario add DONE to `reattach_states`
[2025-08-08T15:38:15.810-0300] {taskinstance.py:1206} INFO - Marking task as FAILED. dag_id=exportar_bq_para_gcs_csv, task_id=exportar_tabela_bq_gcs, run_id=scheduled__2025-08-07T10:00:00+00:00, execution_date=20250807T100000, start_date=20250808T183814, end_date=20250808T183815
[2025-08-08T15:38:15.820-0300] {standard_task_runner.py:110} ERROR - Failed to execute job 131 for task exportar_tabela_bq_gcs (Job with id: ***_exportar_bq_para_gcs_csv_exportar_tabela_bq_gcs_2025_08_07T10_00_00_00_00_25a7e0156089b94962a331960db9c41f already exists and is in DONE state. If you want to force rerun it consider setting `force_rerun=True`.Or, if you want to reattach in this scenario add DONE to `reattach_states`; 251)
[2025-08-08T15:38:15.851-0300] {local_task_job_runner.py:240} INFO - Task exited with return code 1
[2025-08-08T15:38:15.879-0300] {taskinstance.py:3498} INFO - 0 downstream tasks scheduled from follow-on schedule check
[2025-08-08T15:38:15.883-0300] {local_task_job_runner.py:222} INFO - ::endgroup::
[2025-08-08T15:48:29.393-0300] {local_task_job_runner.py:120} INFO - ::group::Pre task execution logs
[2025-08-08T15:48:29.403-0300] {taskinstance.py:2076} INFO - Dependencies all met for dep_context=non-requeueable deps ti=<TaskInstance: exportar_bq_para_gcs_csv.exportar_tabela_bq_gcs scheduled__2025-08-07T10:00:00+00:00 [queued]>
[2025-08-08T15:48:29.409-0300] {taskinstance.py:2076} INFO - Dependencies all met for dep_context=requeueable deps ti=<TaskInstance: exportar_bq_para_gcs_csv.exportar_tabela_bq_gcs scheduled__2025-08-07T10:00:00+00:00 [queued]>
[2025-08-08T15:48:29.409-0300] {taskinstance.py:2306} INFO - Starting attempt 1 of 1
[2025-08-08T15:48:29.415-0300] {taskinstance.py:2330} INFO - Executing <Task(BigQueryToGCSOperator): exportar_tabela_bq_gcs> on 2025-08-07 10:00:00+00:00
[2025-08-08T15:48:29.421-0300] {standard_task_runner.py:63} INFO - Started process 287 to run task
[2025-08-08T15:48:29.423-0300] {standard_task_runner.py:90} INFO - Running: ['***', 'tasks', 'run', 'exportar_bq_para_gcs_csv', 'exportar_tabela_bq_gcs', 'scheduled__2025-08-07T10:00:00+00:00', '--job-id', '141', '--raw', '--subdir', 'DAGS_FOLDER/notas_ordem.py', '--cfg-path', '/tmp/tmp5mofk0ia']
[2025-08-08T15:48:29.425-0300] {standard_task_runner.py:91} INFO - Job 141: Subtask exportar_tabela_bq_gcs
[2025-08-08T15:48:29.452-0300] {task_command.py:426} INFO - Running <TaskInstance: exportar_bq_para_gcs_csv.exportar_tabela_bq_gcs scheduled__2025-08-07T10:00:00+00:00 [running]> on host 6f99aecc4c0e
[2025-08-08T15:48:29.500-0300] {taskinstance.py:2648} INFO - Exporting env vars: AIRFLOW_CTX_DAG_OWNER='***' AIRFLOW_CTX_DAG_ID='exportar_bq_para_gcs_csv' AIRFLOW_CTX_TASK_ID='exportar_tabela_bq_gcs' AIRFLOW_CTX_EXECUTION_DATE='2025-08-07T10:00:00+00:00' AIRFLOW_CTX_TRY_NUMBER='1' AIRFLOW_CTX_DAG_RUN_ID='scheduled__2025-08-07T10:00:00+00:00'
[2025-08-08T15:48:29.500-0300] {taskinstance.py:430} INFO - ::endgroup::
[2025-08-08T15:48:29.507-0300] {bigquery_to_gcs.py:201} INFO - Executing extract of sz-00022-ws.PLAMI.TMP_NOTAS_ORDENS into: ['gs://***_vps/nota_ordem.csv']
[2025-08-08T15:48:29.508-0300] {crypto.py:82} WARNING - empty cryptography key - values will not be stored encrypted.
[2025-08-08T15:48:29.508-0300] {connection.py:274} WARNING - Connection schemes (type: google_cloud_platform) shall not contain '_' according to RFC3986.
[2025-08-08T15:48:29.509-0300] {base.py:84} INFO - Using connection ID 'google_cloud_default' for task execution.
[2025-08-08T15:48:29.544-0300] {bigquery_to_gcs.py:224} INFO - Executing: {'extract': {'sourceTable': {'projectId': 'sz-00022-ws', 'datasetId': 'PLAMI', 'tableId': 'TMP_NOTAS_ORDENS'}, 'compression': 'NONE', 'destinationUris': ['gs://***_vps/nota_ordem.csv'], 'destinationFormat': 'CSV', 'fieldDelimiter': '\x1f', 'printHeader': True}}
[2025-08-08T15:48:29.545-0300] {bigquery.py:1660} INFO - Inserting job ***_exportar_bq_para_gcs_csv_exportar_tabela_bq_gcs_2025_08_07T10_00_00_00_00_25a7e0156089b94962a331960db9c41f
[2025-08-08T15:48:31.135-0300] {taskinstance.py:441} INFO - ::group::Post task execution logs
[2025-08-08T15:48:31.148-0300] {taskinstance.py:2905} ERROR - Task failed with exception
Traceback (most recent call last):
  File "/home/airflow/.local/lib/python3.11/site-packages/airflow/providers/google/cloud/transfers/bigquery_to_gcs.py", line 225, in execute
    job: BigQueryJob | UnknownJob = self._submit_job(
                                    ^^^^^^^^^^^^^^^^^
  File "/home/airflow/.local/lib/python3.11/site-packages/airflow/providers/google/cloud/transfers/bigquery_to_gcs.py", line 190, in _submit_job
    return hook.insert_job(
           ^^^^^^^^^^^^^^^^
  File "/home/airflow/.local/lib/python3.11/site-packages/airflow/providers/google/common/hooks/base_google.py", line 486, in inner_wrapper
    return func(self, *args, **kwargs)
           ^^^^^^^^^^^^^^^^^^^^^^^^^^^
  File "/home/airflow/.local/lib/python3.11/site-packages/airflow/providers/google/cloud/hooks/bigquery.py", line 1666, in insert_job
    job_api_repr.result(timeout=timeout, retry=retry)
  File "/home/airflow/.local/lib/python3.11/site-packages/google/cloud/bigquery/job/base.py", line 968, in result
    self._begin(retry=retry, timeout=timeout)
  File "/home/airflow/.local/lib/python3.11/site-packages/google/cloud/bigquery/job/base.py", line 740, in _begin
    api_response = client._call_api(
                   ^^^^^^^^^^^^^^^^^
  File "/home/airflow/.local/lib/python3.11/site-packages/google/cloud/bigquery/client.py", line 831, in _call_api
    return call()
           ^^^^^^
  File "/home/airflow/.local/lib/python3.11/site-packages/google/api_core/retry/retry_unary.py", line 293, in retry_wrapped_func
    return retry_target(
           ^^^^^^^^^^^^^
  File "/home/airflow/.local/lib/python3.11/site-packages/google/api_core/retry/retry_unary.py", line 153, in retry_target
    _retry_error_helper(
  File "/home/airflow/.local/lib/python3.11/site-packages/google/api_core/retry/retry_base.py", line 212, in _retry_error_helper
    raise final_exc from source_exc
  File "/home/airflow/.local/lib/python3.11/site-packages/google/api_core/retry/retry_unary.py", line 144, in retry_target
    result = target()
             ^^^^^^^^
  File "/home/airflow/.local/lib/python3.11/site-packages/google/cloud/_http/__init__.py", line 494, in api_request
    raise exceptions.from_http_response(response)
google.api_core.exceptions.Conflict: 409 POST https://bigquery.googleapis.com/bigquery/v2/projects/sz-00022-ws/jobs?prettyPrint=false: Already Exists: Job sz-00022-ws:southamerica-east1.airflow_exportar_bq_para_gcs_csv_exportar_tabela_bq_gcs_2025_08_07T10_00_00_00_00_25a7e0156089b94962a331960db9c41f

During handling of the above exception, another exception occurred:

Traceback (most recent call last):
  File "/home/airflow/.local/lib/python3.11/site-packages/airflow/models/taskinstance.py", line 465, in _execute_task
    result = _execute_callable(context=context, **execute_callable_kwargs)
             ^^^^^^^^^^^^^^^^^^^^^^^^^^^^^^^^^^^^^^^^^^^^^^^^^^^^^^^^^^^^^
  File "/home/airflow/.local/lib/python3.11/site-packages/airflow/models/taskinstance.py", line 432, in _execute_callable
    return execute_callable(context=context, **execute_callable_kwargs)
           ^^^^^^^^^^^^^^^^^^^^^^^^^^^^^^^^^^^^^^^^^^^^^^^^^^^^^^^^^^^^
  File "/home/airflow/.local/lib/python3.11/site-packages/airflow/models/baseoperator.py", line 400, in wrapper
    return func(self, *args, **kwargs)
           ^^^^^^^^^^^^^^^^^^^^^^^^^^^
  File "/home/airflow/.local/lib/python3.11/site-packages/airflow/providers/google/cloud/transfers/bigquery_to_gcs.py", line 241, in execute
    raise AirflowException(
airflow.exceptions.AirflowException: Job with id: ***_exportar_bq_para_gcs_csv_exportar_tabela_bq_gcs_2025_08_07T10_00_00_00_00_25a7e0156089b94962a331960db9c41f already exists and is in DONE state. If you want to force rerun it consider setting `force_rerun=True`.Or, if you want to reattach in this scenario add DONE to `reattach_states`
[2025-08-08T15:48:31.158-0300] {taskinstance.py:1206} INFO - Marking task as FAILED. dag_id=exportar_bq_para_gcs_csv, task_id=exportar_tabela_bq_gcs, run_id=scheduled__2025-08-07T10:00:00+00:00, execution_date=20250807T100000, start_date=20250808T184829, end_date=20250808T184831
[2025-08-08T15:48:31.169-0300] {standard_task_runner.py:110} ERROR - Failed to execute job 141 for task exportar_tabela_bq_gcs (Job with id: ***_exportar_bq_para_gcs_csv_exportar_tabela_bq_gcs_2025_08_07T10_00_00_00_00_25a7e0156089b94962a331960db9c41f already exists and is in DONE state. If you want to force rerun it consider setting `force_rerun=True`.Or, if you want to reattach in this scenario add DONE to `reattach_states`; 287)
[2025-08-08T15:48:31.201-0300] {local_task_job_runner.py:240} INFO - Task exited with return code 1
[2025-08-08T15:48:31.229-0300] {taskinstance.py:3498} INFO - 0 downstream tasks scheduled from follow-on schedule check
[2025-08-08T15:48:31.232-0300] {local_task_job_runner.py:222} INFO - ::endgroup::
[2025-08-08T15:49:58.954-0300] {local_task_job_runner.py:120} INFO - ::group::Pre task execution logs
[2025-08-08T15:49:58.964-0300] {taskinstance.py:2076} INFO - Dependencies all met for dep_context=non-requeueable deps ti=<TaskInstance: exportar_bq_para_gcs_csv.exportar_tabela_bq_gcs scheduled__2025-08-07T10:00:00+00:00 [queued]>
[2025-08-08T15:49:58.968-0300] {taskinstance.py:2076} INFO - Dependencies all met for dep_context=requeueable deps ti=<TaskInstance: exportar_bq_para_gcs_csv.exportar_tabela_bq_gcs scheduled__2025-08-07T10:00:00+00:00 [queued]>
[2025-08-08T15:49:58.968-0300] {taskinstance.py:2306} INFO - Starting attempt 1 of 1
[2025-08-08T15:49:58.974-0300] {taskinstance.py:2330} INFO - Executing <Task(BigQueryToGCSOperator): exportar_tabela_bq_gcs> on 2025-08-07 10:00:00+00:00
[2025-08-08T15:49:58.980-0300] {standard_task_runner.py:63} INFO - Started process 331 to run task
[2025-08-08T15:49:58.981-0300] {standard_task_runner.py:90} INFO - Running: ['***', 'tasks', 'run', 'exportar_bq_para_gcs_csv', 'exportar_tabela_bq_gcs', 'scheduled__2025-08-07T10:00:00+00:00', '--job-id', '147', '--raw', '--subdir', 'DAGS_FOLDER/notas_ordem.py', '--cfg-path', '/tmp/tmpi2izsgra']
[2025-08-08T15:49:58.983-0300] {standard_task_runner.py:91} INFO - Job 147: Subtask exportar_tabela_bq_gcs
[2025-08-08T15:49:59.008-0300] {task_command.py:426} INFO - Running <TaskInstance: exportar_bq_para_gcs_csv.exportar_tabela_bq_gcs scheduled__2025-08-07T10:00:00+00:00 [running]> on host 6f99aecc4c0e
[2025-08-08T15:49:59.057-0300] {taskinstance.py:2648} INFO - Exporting env vars: AIRFLOW_CTX_DAG_OWNER='***' AIRFLOW_CTX_DAG_ID='exportar_bq_para_gcs_csv' AIRFLOW_CTX_TASK_ID='exportar_tabela_bq_gcs' AIRFLOW_CTX_EXECUTION_DATE='2025-08-07T10:00:00+00:00' AIRFLOW_CTX_TRY_NUMBER='1' AIRFLOW_CTX_DAG_RUN_ID='scheduled__2025-08-07T10:00:00+00:00'
[2025-08-08T15:49:59.058-0300] {taskinstance.py:430} INFO - ::endgroup::
[2025-08-08T15:49:59.064-0300] {bigquery_to_gcs.py:201} INFO - Executing extract of sz-00022-ws.PLAMI.TMP_NOTAS_ORDENS into: ['gs://***_vps/nota_ordem.csv']
[2025-08-08T15:49:59.065-0300] {crypto.py:82} WARNING - empty cryptography key - values will not be stored encrypted.
[2025-08-08T15:49:59.065-0300] {connection.py:274} WARNING - Connection schemes (type: google_cloud_platform) shall not contain '_' according to RFC3986.
[2025-08-08T15:49:59.065-0300] {base.py:84} INFO - Using connection ID 'google_cloud_default' for task execution.
[2025-08-08T15:49:59.099-0300] {bigquery_to_gcs.py:224} INFO - Executing: {'extract': {'sourceTable': {'projectId': 'sz-00022-ws', 'datasetId': 'PLAMI', 'tableId': 'TMP_NOTAS_ORDENS'}, 'compression': 'NONE', 'destinationUris': ['gs://***_vps/nota_ordem.csv'], 'destinationFormat': 'CSV', 'fieldDelimiter': '\x1f', 'printHeader': True}}
[2025-08-08T15:49:59.100-0300] {bigquery.py:1660} INFO - Inserting job ***_exportar_bq_para_gcs_csv_exportar_tabela_bq_gcs_2025_08_07T10_00_00_00_00_25a7e0156089b94962a331960db9c41f
[2025-08-08T15:50:00.377-0300] {taskinstance.py:441} INFO - ::group::Post task execution logs
[2025-08-08T15:50:00.385-0300] {taskinstance.py:2905} ERROR - Task failed with exception
Traceback (most recent call last):
  File "/home/airflow/.local/lib/python3.11/site-packages/airflow/providers/google/cloud/transfers/bigquery_to_gcs.py", line 225, in execute
    job: BigQueryJob | UnknownJob = self._submit_job(
                                    ^^^^^^^^^^^^^^^^^
  File "/home/airflow/.local/lib/python3.11/site-packages/airflow/providers/google/cloud/transfers/bigquery_to_gcs.py", line 190, in _submit_job
    return hook.insert_job(
           ^^^^^^^^^^^^^^^^
  File "/home/airflow/.local/lib/python3.11/site-packages/airflow/providers/google/common/hooks/base_google.py", line 486, in inner_wrapper
    return func(self, *args, **kwargs)
           ^^^^^^^^^^^^^^^^^^^^^^^^^^^
  File "/home/airflow/.local/lib/python3.11/site-packages/airflow/providers/google/cloud/hooks/bigquery.py", line 1666, in insert_job
    job_api_repr.result(timeout=timeout, retry=retry)
  File "/home/airflow/.local/lib/python3.11/site-packages/google/cloud/bigquery/job/base.py", line 968, in result
    self._begin(retry=retry, timeout=timeout)
  File "/home/airflow/.local/lib/python3.11/site-packages/google/cloud/bigquery/job/base.py", line 740, in _begin
    api_response = client._call_api(
                   ^^^^^^^^^^^^^^^^^
  File "/home/airflow/.local/lib/python3.11/site-packages/google/cloud/bigquery/client.py", line 831, in _call_api
    return call()
           ^^^^^^
  File "/home/airflow/.local/lib/python3.11/site-packages/google/api_core/retry/retry_unary.py", line 293, in retry_wrapped_func
    return retry_target(
           ^^^^^^^^^^^^^
  File "/home/airflow/.local/lib/python3.11/site-packages/google/api_core/retry/retry_unary.py", line 153, in retry_target
    _retry_error_helper(
  File "/home/airflow/.local/lib/python3.11/site-packages/google/api_core/retry/retry_base.py", line 212, in _retry_error_helper
    raise final_exc from source_exc
  File "/home/airflow/.local/lib/python3.11/site-packages/google/api_core/retry/retry_unary.py", line 144, in retry_target
    result = target()
             ^^^^^^^^
  File "/home/airflow/.local/lib/python3.11/site-packages/google/cloud/_http/__init__.py", line 494, in api_request
    raise exceptions.from_http_response(response)
google.api_core.exceptions.Conflict: 409 POST https://bigquery.googleapis.com/bigquery/v2/projects/sz-00022-ws/jobs?prettyPrint=false: Already Exists: Job sz-00022-ws:southamerica-east1.airflow_exportar_bq_para_gcs_csv_exportar_tabela_bq_gcs_2025_08_07T10_00_00_00_00_25a7e0156089b94962a331960db9c41f

During handling of the above exception, another exception occurred:

Traceback (most recent call last):
  File "/home/airflow/.local/lib/python3.11/site-packages/airflow/models/taskinstance.py", line 465, in _execute_task
    result = _execute_callable(context=context, **execute_callable_kwargs)
             ^^^^^^^^^^^^^^^^^^^^^^^^^^^^^^^^^^^^^^^^^^^^^^^^^^^^^^^^^^^^^
  File "/home/airflow/.local/lib/python3.11/site-packages/airflow/models/taskinstance.py", line 432, in _execute_callable
    return execute_callable(context=context, **execute_callable_kwargs)
           ^^^^^^^^^^^^^^^^^^^^^^^^^^^^^^^^^^^^^^^^^^^^^^^^^^^^^^^^^^^^
  File "/home/airflow/.local/lib/python3.11/site-packages/airflow/models/baseoperator.py", line 400, in wrapper
    return func(self, *args, **kwargs)
           ^^^^^^^^^^^^^^^^^^^^^^^^^^^
  File "/home/airflow/.local/lib/python3.11/site-packages/airflow/providers/google/cloud/transfers/bigquery_to_gcs.py", line 241, in execute
    raise AirflowException(
airflow.exceptions.AirflowException: Job with id: ***_exportar_bq_para_gcs_csv_exportar_tabela_bq_gcs_2025_08_07T10_00_00_00_00_25a7e0156089b94962a331960db9c41f already exists and is in DONE state. If you want to force rerun it consider setting `force_rerun=True`.Or, if you want to reattach in this scenario add DONE to `reattach_states`
[2025-08-08T15:50:00.391-0300] {taskinstance.py:1206} INFO - Marking task as FAILED. dag_id=exportar_bq_para_gcs_csv, task_id=exportar_tabela_bq_gcs, run_id=scheduled__2025-08-07T10:00:00+00:00, execution_date=20250807T100000, start_date=20250808T184958, end_date=20250808T185000
[2025-08-08T15:50:00.402-0300] {standard_task_runner.py:110} ERROR - Failed to execute job 147 for task exportar_tabela_bq_gcs (Job with id: ***_exportar_bq_para_gcs_csv_exportar_tabela_bq_gcs_2025_08_07T10_00_00_00_00_25a7e0156089b94962a331960db9c41f already exists and is in DONE state. If you want to force rerun it consider setting `force_rerun=True`.Or, if you want to reattach in this scenario add DONE to `reattach_states`; 331)
[2025-08-08T15:50:00.437-0300] {local_task_job_runner.py:240} INFO - Task exited with return code 1
[2025-08-08T15:50:00.470-0300] {taskinstance.py:3498} INFO - 0 downstream tasks scheduled from follow-on schedule check
[2025-08-08T15:50:00.474-0300] {local_task_job_runner.py:222} INFO - ::endgroup::
