[2025-08-14T20:00:00.617-0300] {local_task_job_runner.py:120} INFO - ::group::Pre task execution logs
[2025-08-14T20:00:00.631-0300] {taskinstance.py:2076} INFO - Dependencies all met for dep_context=non-requeueable deps ti=<TaskInstance: avisos_coordenador.buscar_variaveis_avisos scheduled__2025-08-14T22:30:00+00:00 [queued]>
[2025-08-14T20:00:00.635-0300] {taskinstance.py:2076} INFO - Dependencies all met for dep_context=requeueable deps ti=<TaskInstance: avisos_coordenador.buscar_variaveis_avisos scheduled__2025-08-14T22:30:00+00:00 [queued]>
[2025-08-14T20:00:00.635-0300] {taskinstance.py:2306} INFO - Starting attempt 1 of 1
[2025-08-14T20:00:00.642-0300] {taskinstance.py:2330} INFO - Executing <Task(PythonOperator): buscar_variaveis_avisos> on 2025-08-14 22:30:00+00:00
[2025-08-14T20:00:00.646-0300] {standard_task_runner.py:63} INFO - Started process 679 to run task
[2025-08-14T20:00:00.647-0300] {standard_task_runner.py:90} INFO - Running: ['***', 'tasks', 'run', 'avisos_coordenador', 'buscar_variaveis_avisos', 'scheduled__2025-08-14T22:30:00+00:00', '--job-id', '215', '--raw', '--subdir', 'DAGS_FOLDER/avisos_coordenador.py', '--cfg-path', '/tmp/tmp96rkzq35']
[2025-08-14T20:00:00.752-0300] {standard_task_runner.py:91} INFO - Job 215: Subtask buscar_variaveis_avisos
[2025-08-14T20:00:00.774-0300] {task_command.py:426} INFO - Running <TaskInstance: avisos_coordenador.buscar_variaveis_avisos scheduled__2025-08-14T22:30:00+00:00 [running]> on host 1a4c58afc681
[2025-08-14T20:00:00.814-0300] {taskinstance.py:2648} INFO - Exporting env vars: AIRFLOW_CTX_DAG_OWNER='***' AIRFLOW_CTX_DAG_ID='avisos_coordenador' AIRFLOW_CTX_TASK_ID='buscar_variaveis_avisos' AIRFLOW_CTX_EXECUTION_DATE='2025-08-14T22:30:00+00:00' AIRFLOW_CTX_TRY_NUMBER='1' AIRFLOW_CTX_DAG_RUN_ID='scheduled__2025-08-14T22:30:00+00:00'
[2025-08-14T20:00:00.815-0300] {taskinstance.py:430} INFO - ::endgroup::
[2025-08-14T20:00:03.923-0300] {taskinstance.py:441} INFO - ::group::Post task execution logs
[2025-08-14T20:00:03.923-0300] {taskinstance.py:2905} ERROR - Task failed with exception
Traceback (most recent call last):
  File "/home/airflow/.local/lib/python3.11/site-packages/airflow/models/taskinstance.py", line 465, in _execute_task
    result = _execute_callable(context=context, **execute_callable_kwargs)
             ^^^^^^^^^^^^^^^^^^^^^^^^^^^^^^^^^^^^^^^^^^^^^^^^^^^^^^^^^^^^^
  File "/home/airflow/.local/lib/python3.11/site-packages/airflow/models/taskinstance.py", line 432, in _execute_callable
    return execute_callable(context=context, **execute_callable_kwargs)
           ^^^^^^^^^^^^^^^^^^^^^^^^^^^^^^^^^^^^^^^^^^^^^^^^^^^^^^^^^^^^
  File "/home/airflow/.local/lib/python3.11/site-packages/airflow/models/baseoperator.py", line 400, in wrapper
    return func(self, *args, **kwargs)
           ^^^^^^^^^^^^^^^^^^^^^^^^^^^
  File "/home/airflow/.local/lib/python3.11/site-packages/airflow/operators/python.py", line 235, in execute
    return_value = self.execute_callable()
                   ^^^^^^^^^^^^^^^^^^^^^^^
  File "/home/airflow/.local/lib/python3.11/site-packages/airflow/operators/python.py", line 252, in execute_callable
    return self.python_callable(*self.op_args, **self.op_kwargs)
           ^^^^^^^^^^^^^^^^^^^^^^^^^^^^^^^^^^^^^^^^^^^^^^^^^^^^^
  File "/opt/airflow/dags/avisos_coordenador.py", line 206, in buscar_variaveis_avisos
    conn = get_conn()
           ^^^^^^^^^^
  File "/opt/airflow/dags/avisos_coordenador.py", line 38, in get_conn
    return psycopg2.connect(os.getenv("PG_CONN"))
           ^^^^^^^^^^^^^^^^^^^^^^^^^^^^^^^^^^^^^^
  File "/home/airflow/.local/lib/python3.11/site-packages/psycopg2/__init__.py", line 122, in connect
    conn = _connect(dsn, connection_factory=connection_factory, **kwasync)
           ^^^^^^^^^^^^^^^^^^^^^^^^^^^^^^^^^^^^^^^^^^^^^^^^^^^^^^^^^^^^^^^
psycopg2.OperationalError: connection to server at "10.66.66.1", port 6432 failed: No route to host
	Is the server running on that host and accepting TCP/IP connections?

[2025-08-14T20:00:03.934-0300] {taskinstance.py:1206} INFO - Marking task as FAILED. dag_id=avisos_coordenador, task_id=buscar_variaveis_avisos, run_id=scheduled__2025-08-14T22:30:00+00:00, execution_date=20250814T223000, start_date=20250814T230000, end_date=20250814T230003
[2025-08-14T20:00:03.954-0300] {standard_task_runner.py:110} ERROR - Failed to execute job 215 for task buscar_variaveis_avisos (connection to server at "10.66.66.1", port 6432 failed: No route to host
	Is the server running on that host and accepting TCP/IP connections?
; 679)
[2025-08-14T20:00:03.968-0300] {local_task_job_runner.py:240} INFO - Task exited with return code 1
[2025-08-14T20:00:04.064-0300] {taskinstance.py:3498} INFO - 0 downstream tasks scheduled from follow-on schedule check
[2025-08-14T20:00:04.068-0300] {local_task_job_runner.py:222} INFO - ::endgroup::
