[2025-07-31T16:19:14.770-0300] {local_task_job_runner.py:120} INFO - ::group::Pre task execution logs
[2025-07-31T16:19:14.871-0300] {taskinstance.py:2076} INFO - Dependencies all met for dep_context=non-requeueable deps ti=<TaskInstance: exportar_bq_para_gcs_csv.exportar_tabela_bq_gcs manual__2025-07-31T19:19:13.445812+00:00 [queued]>
[2025-07-31T16:19:14.877-0300] {taskinstance.py:2076} INFO - Dependencies all met for dep_context=requeueable deps ti=<TaskInstance: exportar_bq_para_gcs_csv.exportar_tabela_bq_gcs manual__2025-07-31T19:19:13.445812+00:00 [queued]>
[2025-07-31T16:19:14.877-0300] {taskinstance.py:2306} INFO - Starting attempt 1 of 1
[2025-07-31T16:19:14.886-0300] {taskinstance.py:2330} INFO - Executing <Task(BigQueryToGCSOperator): exportar_tabela_bq_gcs> on 2025-07-31 19:19:13.445812+00:00
[2025-07-31T16:19:14.890-0300] {standard_task_runner.py:63} INFO - Started process 180 to run task
[2025-07-31T16:19:14.892-0300] {standard_task_runner.py:90} INFO - Running: ['***', 'tasks', 'run', 'exportar_bq_para_gcs_csv', 'exportar_tabela_bq_gcs', 'manual__2025-07-31T19:19:13.445812+00:00', '--job-id', '2', '--raw', '--subdir', 'DAGS_FOLDER/notas_ordem.py', '--cfg-path', '/tmp/tmp_h8jw03e']
[2025-07-31T16:19:14.893-0300] {standard_task_runner.py:91} INFO - Job 2: Subtask exportar_tabela_bq_gcs
[2025-07-31T16:19:14.928-0300] {task_command.py:426} INFO - Running <TaskInstance: exportar_bq_para_gcs_csv.exportar_tabela_bq_gcs manual__2025-07-31T19:19:13.445812+00:00 [running]> on host ef469486623e
[2025-07-31T16:19:14.981-0300] {taskinstance.py:2648} INFO - Exporting env vars: AIRFLOW_CTX_DAG_OWNER='***' AIRFLOW_CTX_DAG_ID='exportar_bq_para_gcs_csv' AIRFLOW_CTX_TASK_ID='exportar_tabela_bq_gcs' AIRFLOW_CTX_EXECUTION_DATE='2025-07-31T19:19:13.445812+00:00' AIRFLOW_CTX_TRY_NUMBER='1' AIRFLOW_CTX_DAG_RUN_ID='manual__2025-07-31T19:19:13.445812+00:00'
[2025-07-31T16:19:14.982-0300] {taskinstance.py:430} INFO - ::endgroup::
[2025-07-31T16:19:15.007-0300] {bigquery_to_gcs.py:201} INFO - Executing extract of sz-00022-ws.PLAMI.NOTAS_ORDENS into: ['gs://***_vps/nota_ordem.csv']
[2025-07-31T16:19:15.007-0300] {connection.py:513} ERROR - Unable to retrieve connection from secrets backend (EnvironmentVariablesBackend). Checking subsequent secrets backend.
Traceback (most recent call last):
  File "/home/airflow/.local/lib/python3.11/site-packages/airflow/models/connection.py", line 508, in get_connection_from_secrets
    conn = secrets_backend.get_connection(conn_id=conn_id)
           ^^^^^^^^^^^^^^^^^^^^^^^^^^^^^^^^^^^^^^^^^^^^^^^
  File "/home/airflow/.local/lib/python3.11/site-packages/airflow/secrets/base_secrets.py", line 116, in get_connection
    return self.deserialize_connection(conn_id=conn_id, value=value)
           ^^^^^^^^^^^^^^^^^^^^^^^^^^^^^^^^^^^^^^^^^^^^^^^^^^^^^^^^^
  File "/home/airflow/.local/lib/python3.11/site-packages/airflow/secrets/base_secrets.py", line 68, in deserialize_connection
    return Connection.from_json(conn_id=conn_id, value=value)
           ^^^^^^^^^^^^^^^^^^^^^^^^^^^^^^^^^^^^^^^^^^^^^^^^^^
  File "/home/airflow/.local/lib/python3.11/site-packages/airflow/models/connection.py", line 564, in from_json
    return Connection(conn_id=conn_id, **kwargs)
           ^^^^^^^^^^^^^^^^^^^^^^^^^^^^^^^^^^^^^
TypeError: __init__() got an unexpected keyword argument 'extra__google_cloud_platform__project'
[2025-07-31T16:19:15.013-0300] {connection.py:274} WARNING - Connection schemes (type: google_cloud_platform) shall not contain '_' according to RFC3986.
[2025-07-31T16:19:15.013-0300] {base.py:84} INFO - Using connection ID 'google_cloud_default' for task execution.
[2025-07-31T16:19:15.013-0300] {credentials_provider.py:353} INFO - Getting connection using `google.auth.default()` since no explicit credentials are provided.
[2025-07-31T16:19:15.063-0300] {bigquery_to_gcs.py:224} INFO - Executing: {'extract': {'sourceTable': {'projectId': 'sz-00022-ws', 'datasetId': 'PLAMI', 'tableId': 'NOTAS_ORDENS'}, 'compression': 'NONE', 'destinationUris': ['gs://***_vps/nota_ordem.csv'], 'destinationFormat': 'CSV', 'fieldDelimiter': '\x1f', 'printHeader': True}}
[2025-07-31T16:19:15.064-0300] {bigquery.py:1660} INFO - Inserting job ***_exportar_bq_para_gcs_csv_exportar_tabela_bq_gcs_2025_07_31T19_19_13_445812_00_00_0eca8a5b858381082235fcc913e0f779
[2025-07-31T16:19:15.740-0300] {taskinstance.py:441} INFO - ::group::Post task execution logs
[2025-07-31T16:19:15.741-0300] {taskinstance.py:2905} ERROR - Task failed with exception
Traceback (most recent call last):
  File "/home/airflow/.local/lib/python3.11/site-packages/airflow/models/taskinstance.py", line 465, in _execute_task
    result = _execute_callable(context=context, **execute_callable_kwargs)
             ^^^^^^^^^^^^^^^^^^^^^^^^^^^^^^^^^^^^^^^^^^^^^^^^^^^^^^^^^^^^^
  File "/home/airflow/.local/lib/python3.11/site-packages/airflow/models/taskinstance.py", line 432, in _execute_callable
    return execute_callable(context=context, **execute_callable_kwargs)
           ^^^^^^^^^^^^^^^^^^^^^^^^^^^^^^^^^^^^^^^^^^^^^^^^^^^^^^^^^^^^
  File "/home/airflow/.local/lib/python3.11/site-packages/airflow/models/baseoperator.py", line 400, in wrapper
    return func(self, *args, **kwargs)
           ^^^^^^^^^^^^^^^^^^^^^^^^^^^
  File "/home/airflow/.local/lib/python3.11/site-packages/airflow/providers/google/cloud/transfers/bigquery_to_gcs.py", line 225, in execute
    job: BigQueryJob | UnknownJob = self._submit_job(
                                    ^^^^^^^^^^^^^^^^^
  File "/home/airflow/.local/lib/python3.11/site-packages/airflow/providers/google/cloud/transfers/bigquery_to_gcs.py", line 190, in _submit_job
    return hook.insert_job(
           ^^^^^^^^^^^^^^^^
  File "/home/airflow/.local/lib/python3.11/site-packages/airflow/providers/google/common/hooks/base_google.py", line 486, in inner_wrapper
    return func(self, *args, **kwargs)
           ^^^^^^^^^^^^^^^^^^^^^^^^^^^
  File "/home/airflow/.local/lib/python3.11/site-packages/airflow/providers/google/cloud/hooks/bigquery.py", line 1666, in insert_job
    job_api_repr.result(timeout=timeout, retry=retry)
  File "/home/airflow/.local/lib/python3.11/site-packages/google/cloud/bigquery/job/base.py", line 971, in result
    return super(_AsyncJob, self).result(timeout=timeout, **kwargs)
           ^^^^^^^^^^^^^^^^^^^^^^^^^^^^^^^^^^^^^^^^^^^^^^^^^^^^^^^^
  File "/home/airflow/.local/lib/python3.11/site-packages/google/api_core/future/polling.py", line 261, in result
    raise self._exception
google.api_core.exceptions.BadRequest: 400 sz-00022-ws:PLAMI.NOTAS_ORDENS is not allowed for this operation because it currently has type VIEW.; reason: invalid, message: sz-00022-ws:PLAMI.NOTAS_ORDENS is not allowed for this operation because it currently has type VIEW.
[2025-07-31T16:19:15.754-0300] {taskinstance.py:1206} INFO - Marking task as FAILED. dag_id=exportar_bq_para_gcs_csv, task_id=exportar_tabela_bq_gcs, run_id=manual__2025-07-31T19:19:13.445812+00:00, execution_date=20250731T191913, start_date=20250731T191914, end_date=20250731T191915
[2025-07-31T16:19:15.771-0300] {standard_task_runner.py:110} ERROR - Failed to execute job 2 for task exportar_tabela_bq_gcs (400 sz-00022-ws:PLAMI.NOTAS_ORDENS is not allowed for this operation because it currently has type VIEW.; reason: invalid, message: sz-00022-ws:PLAMI.NOTAS_ORDENS is not allowed for this operation because it currently has type VIEW.; 180)
[2025-07-31T16:19:15.786-0300] {local_task_job_runner.py:240} INFO - Task exited with return code 1
[2025-07-31T16:19:15.795-0300] {taskinstance.py:3498} INFO - 0 downstream tasks scheduled from follow-on schedule check
[2025-07-31T16:19:15.796-0300] {local_task_job_runner.py:222} INFO - ::endgroup::
