[2025-08-08T17:09:28.918-0300] {local_task_job_runner.py:120} INFO - ::group::Pre task execution logs
[2025-08-08T17:09:28.933-0300] {taskinstance.py:2076} INFO - Dependencies all met for dep_context=non-requeueable deps ti=<TaskInstance: avisos_coordenador.consultar_valores_pi manual__2025-08-08T20:09:26.243666+00:00 [queued]>
[2025-08-08T17:09:28.937-0300] {taskinstance.py:2076} INFO - Dependencies all met for dep_context=requeueable deps ti=<TaskInstance: avisos_coordenador.consultar_valores_pi manual__2025-08-08T20:09:26.243666+00:00 [queued]>
[2025-08-08T17:09:28.937-0300] {taskinstance.py:2306} INFO - Starting attempt 1 of 1
[2025-08-08T17:09:29.032-0300] {taskinstance.py:2330} INFO - Executing <Task(PythonOperator): consultar_valores_pi> on 2025-08-08 20:09:26.243666+00:00
[2025-08-08T17:09:29.037-0300] {standard_task_runner.py:63} INFO - Started process 796 to run task
[2025-08-08T17:09:29.038-0300] {standard_task_runner.py:90} INFO - Running: ['***', 'tasks', 'run', 'avisos_coordenador', 'consultar_valores_pi', 'manual__2025-08-08T20:09:26.243666+00:00', '--job-id', '173', '--raw', '--subdir', 'DAGS_FOLDER/avisos_coordenador.py', '--cfg-path', '/tmp/tmpi4vptjzy']
[2025-08-08T17:09:29.040-0300] {standard_task_runner.py:91} INFO - Job 173: Subtask consultar_valores_pi
[2025-08-08T17:09:29.063-0300] {task_command.py:426} INFO - Running <TaskInstance: avisos_coordenador.consultar_valores_pi manual__2025-08-08T20:09:26.243666+00:00 [running]> on host 1a4c58afc681
[2025-08-08T17:09:29.107-0300] {taskinstance.py:2648} INFO - Exporting env vars: AIRFLOW_CTX_DAG_OWNER='***' AIRFLOW_CTX_DAG_ID='avisos_coordenador' AIRFLOW_CTX_TASK_ID='consultar_valores_pi' AIRFLOW_CTX_EXECUTION_DATE='2025-08-08T20:09:26.243666+00:00' AIRFLOW_CTX_TRY_NUMBER='1' AIRFLOW_CTX_DAG_RUN_ID='manual__2025-08-08T20:09:26.243666+00:00'
[2025-08-08T17:09:29.108-0300] {taskinstance.py:430} INFO - ::endgroup::
[2025-08-08T17:09:29.612-0300] {logging_mixin.py:188} INFO - üö® Aviso id_alarme=1 disparado. Sil√™ncio at√© 2025-08-08T20:10:29.611746+00:00
[2025-08-08T17:09:33.127-0300] {logging_mixin.py:188} INFO - üì® Mensagem gerada:
[2025-08-08T17:09:33.127-0300] {logging_mixin.py:188} INFO -  Prezados/as,

Espero que estejam bem.

Venho por meio desta mensagem chamar a aten√ß√£o para um desvio identificado na gest√£o ambiental de nosso processo.

Conforme evidenciado no gr√°fico de tend√™ncia em anexo, a m√©dia de vaz√£o dos efluentes gerados durante a produ√ß√£o de papel tem superado o limite estabelecido em nosso programa de excel√™ncia operacional. Esse limite foi determinado com base na capacidade m√°xima da esta√ß√£o de tratamento de efluentes especificamente destinada ao processo de fabrica√ß√£o de papel.

Vaz√£o M√©dia (2 horas): 214,18 m¬≥/h.
[2025-08-08T17:09:33.137-0300] {taskinstance.py:441} INFO - ::group::Post task execution logs
[2025-08-08T17:09:33.138-0300] {taskinstance.py:2905} ERROR - Task failed with exception
Traceback (most recent call last):
  File "/home/airflow/.local/lib/python3.11/site-packages/airflow/models/taskinstance.py", line 465, in _execute_task
    result = _execute_callable(context=context, **execute_callable_kwargs)
             ^^^^^^^^^^^^^^^^^^^^^^^^^^^^^^^^^^^^^^^^^^^^^^^^^^^^^^^^^^^^^
  File "/home/airflow/.local/lib/python3.11/site-packages/airflow/models/taskinstance.py", line 432, in _execute_callable
    return execute_callable(context=context, **execute_callable_kwargs)
           ^^^^^^^^^^^^^^^^^^^^^^^^^^^^^^^^^^^^^^^^^^^^^^^^^^^^^^^^^^^^
  File "/home/airflow/.local/lib/python3.11/site-packages/airflow/models/baseoperator.py", line 400, in wrapper
    return func(self, *args, **kwargs)
           ^^^^^^^^^^^^^^^^^^^^^^^^^^^
  File "/home/airflow/.local/lib/python3.11/site-packages/airflow/operators/python.py", line 235, in execute
    return_value = self.execute_callable()
                   ^^^^^^^^^^^^^^^^^^^^^^^
  File "/home/airflow/.local/lib/python3.11/site-packages/airflow/operators/python.py", line 252, in execute_callable
    return self.python_callable(*self.op_args, **self.op_kwargs)
           ^^^^^^^^^^^^^^^^^^^^^^^^^^^^^^^^^^^^^^^^^^^^^^^^^^^^^
  File "/opt/airflow/dags/avisos_coordenador.py", line 293, in consultar_valores_pi
    grafico_b64 = gerar_grafico_trend_base64(
                  ^^^^^^^^^^^^^^^^^^^^^^^^^^^
  File "/opt/airflow/dags/avisos_coordenador.py", line 172, in gerar_grafico_trend_base64
    plt.gca().xaxis.set_major_formatter(mdates.DateFormatter('%H:%M'))
                                        ^^^^^^
NameError: name 'mdates' is not defined
[2025-08-08T17:09:33.148-0300] {taskinstance.py:1206} INFO - Marking task as FAILED. dag_id=avisos_coordenador, task_id=consultar_valores_pi, run_id=manual__2025-08-08T20:09:26.243666+00:00, execution_date=20250808T200926, start_date=20250808T200928, end_date=20250808T200933
[2025-08-08T17:09:33.157-0300] {standard_task_runner.py:110} ERROR - Failed to execute job 173 for task consultar_valores_pi (name 'mdates' is not defined; 796)
[2025-08-08T17:09:33.183-0300] {local_task_job_runner.py:240} INFO - Task exited with return code 1
[2025-08-08T17:09:33.195-0300] {taskinstance.py:3498} INFO - 0 downstream tasks scheduled from follow-on schedule check
[2025-08-08T17:09:33.196-0300] {local_task_job_runner.py:222} INFO - ::endgroup::
