[2025-08-15T09:00:43.058-0300] {local_task_job_runner.py:120} INFO - ::group::Pre task execution logs
[2025-08-15T09:00:43.066-0300] {taskinstance.py:2076} INFO - Dependencies all met for dep_context=non-requeueable deps ti=<TaskInstance: exportar_bq_para_gcs_csv.exportar_tabela_bq_gcs scheduled__2025-08-14T10:00:00+00:00 [queued]>
[2025-08-15T09:00:43.069-0300] {taskinstance.py:2076} INFO - Dependencies all met for dep_context=requeueable deps ti=<TaskInstance: exportar_bq_para_gcs_csv.exportar_tabela_bq_gcs scheduled__2025-08-14T10:00:00+00:00 [queued]>
[2025-08-15T09:00:43.070-0300] {taskinstance.py:2306} INFO - Starting attempt 1 of 1
[2025-08-15T09:00:43.076-0300] {taskinstance.py:2330} INFO - Executing <Task(BigQueryToGCSOperator): exportar_tabela_bq_gcs> on 2025-08-14 10:00:00+00:00
[2025-08-15T09:00:43.080-0300] {standard_task_runner.py:63} INFO - Started process 243 to run task
[2025-08-15T09:00:43.082-0300] {standard_task_runner.py:90} INFO - Running: ['***', 'tasks', 'run', 'exportar_bq_para_gcs_csv', 'exportar_tabela_bq_gcs', 'scheduled__2025-08-14T10:00:00+00:00', '--job-id', '223', '--raw', '--subdir', 'DAGS_FOLDER/notas_ordem.py', '--cfg-path', '/tmp/tmpw1pb4dqj']
[2025-08-15T09:00:43.083-0300] {standard_task_runner.py:91} INFO - Job 223: Subtask exportar_tabela_bq_gcs
[2025-08-15T09:00:43.108-0300] {task_command.py:426} INFO - Running <TaskInstance: exportar_bq_para_gcs_csv.exportar_tabela_bq_gcs scheduled__2025-08-14T10:00:00+00:00 [running]> on host 3c38c83cef21
[2025-08-15T09:00:43.152-0300] {taskinstance.py:2648} INFO - Exporting env vars: AIRFLOW_CTX_DAG_OWNER='***' AIRFLOW_CTX_DAG_ID='exportar_bq_para_gcs_csv' AIRFLOW_CTX_TASK_ID='exportar_tabela_bq_gcs' AIRFLOW_CTX_EXECUTION_DATE='2025-08-14T10:00:00+00:00' AIRFLOW_CTX_TRY_NUMBER='1' AIRFLOW_CTX_DAG_RUN_ID='scheduled__2025-08-14T10:00:00+00:00'
[2025-08-15T09:00:43.152-0300] {taskinstance.py:430} INFO - ::endgroup::
[2025-08-15T09:00:43.158-0300] {bigquery_to_gcs.py:201} INFO - Executing extract of sz-00022-ws.PLAMI.TMP_NOTAS_ORDENS into: ['gs://***_vps/nota_ordem.csv']
[2025-08-15T09:00:43.159-0300] {crypto.py:82} WARNING - empty cryptography key - values will not be stored encrypted.
[2025-08-15T09:00:43.159-0300] {connection.py:274} WARNING - Connection schemes (type: google_cloud_platform) shall not contain '_' according to RFC3986.
[2025-08-15T09:00:43.159-0300] {base.py:84} INFO - Using connection ID 'google_cloud_default' for task execution.
[2025-08-15T09:00:43.192-0300] {bigquery_to_gcs.py:224} INFO - Executing: {'extract': {'sourceTable': {'projectId': 'sz-00022-ws', 'datasetId': 'PLAMI', 'tableId': 'TMP_NOTAS_ORDENS'}, 'compression': 'NONE', 'destinationUris': ['gs://***_vps/nota_ordem.csv'], 'destinationFormat': 'CSV', 'fieldDelimiter': '\x1f', 'printHeader': True}}
[2025-08-15T09:00:43.193-0300] {bigquery.py:1660} INFO - Inserting job ***_exportar_bq_para_gcs_csv_exportar_tabela_bq_gcs_2025_08_14T10_00_00_00_00_25a7e0156089b94962a331960db9c41f
[2025-08-15T09:00:44.788-0300] {taskinstance.py:441} INFO - ::group::Post task execution logs
[2025-08-15T09:00:44.793-0300] {taskinstance.py:2905} ERROR - Task failed with exception
Traceback (most recent call last):
  File "/home/airflow/.local/lib/python3.11/site-packages/airflow/providers/google/cloud/transfers/bigquery_to_gcs.py", line 225, in execute
    job: BigQueryJob | UnknownJob = self._submit_job(
                                    ^^^^^^^^^^^^^^^^^
  File "/home/airflow/.local/lib/python3.11/site-packages/airflow/providers/google/cloud/transfers/bigquery_to_gcs.py", line 190, in _submit_job
    return hook.insert_job(
           ^^^^^^^^^^^^^^^^
  File "/home/airflow/.local/lib/python3.11/site-packages/airflow/providers/google/common/hooks/base_google.py", line 486, in inner_wrapper
    return func(self, *args, **kwargs)
           ^^^^^^^^^^^^^^^^^^^^^^^^^^^
  File "/home/airflow/.local/lib/python3.11/site-packages/airflow/providers/google/cloud/hooks/bigquery.py", line 1666, in insert_job
    job_api_repr.result(timeout=timeout, retry=retry)
  File "/home/airflow/.local/lib/python3.11/site-packages/google/cloud/bigquery/job/base.py", line 968, in result
    self._begin(retry=retry, timeout=timeout)
  File "/home/airflow/.local/lib/python3.11/site-packages/google/cloud/bigquery/job/base.py", line 740, in _begin
    api_response = client._call_api(
                   ^^^^^^^^^^^^^^^^^
  File "/home/airflow/.local/lib/python3.11/site-packages/google/cloud/bigquery/client.py", line 831, in _call_api
    return call()
           ^^^^^^
  File "/home/airflow/.local/lib/python3.11/site-packages/google/api_core/retry/retry_unary.py", line 293, in retry_wrapped_func
    return retry_target(
           ^^^^^^^^^^^^^
  File "/home/airflow/.local/lib/python3.11/site-packages/google/api_core/retry/retry_unary.py", line 153, in retry_target
    _retry_error_helper(
  File "/home/airflow/.local/lib/python3.11/site-packages/google/api_core/retry/retry_base.py", line 212, in _retry_error_helper
    raise final_exc from source_exc
  File "/home/airflow/.local/lib/python3.11/site-packages/google/api_core/retry/retry_unary.py", line 144, in retry_target
    result = target()
             ^^^^^^^^
  File "/home/airflow/.local/lib/python3.11/site-packages/google/cloud/_http/__init__.py", line 494, in api_request
    raise exceptions.from_http_response(response)
google.api_core.exceptions.Conflict: 409 POST https://bigquery.googleapis.com/bigquery/v2/projects/sz-00022-ws/jobs?prettyPrint=false: Already Exists: Job sz-00022-ws:southamerica-east1.airflow_exportar_bq_para_gcs_csv_exportar_tabela_bq_gcs_2025_08_14T10_00_00_00_00_25a7e0156089b94962a331960db9c41f

During handling of the above exception, another exception occurred:

Traceback (most recent call last):
  File "/home/airflow/.local/lib/python3.11/site-packages/airflow/models/taskinstance.py", line 465, in _execute_task
    result = _execute_callable(context=context, **execute_callable_kwargs)
             ^^^^^^^^^^^^^^^^^^^^^^^^^^^^^^^^^^^^^^^^^^^^^^^^^^^^^^^^^^^^^
  File "/home/airflow/.local/lib/python3.11/site-packages/airflow/models/taskinstance.py", line 432, in _execute_callable
    return execute_callable(context=context, **execute_callable_kwargs)
           ^^^^^^^^^^^^^^^^^^^^^^^^^^^^^^^^^^^^^^^^^^^^^^^^^^^^^^^^^^^^
  File "/home/airflow/.local/lib/python3.11/site-packages/airflow/models/baseoperator.py", line 400, in wrapper
    return func(self, *args, **kwargs)
           ^^^^^^^^^^^^^^^^^^^^^^^^^^^
  File "/home/airflow/.local/lib/python3.11/site-packages/airflow/providers/google/cloud/transfers/bigquery_to_gcs.py", line 241, in execute
    raise AirflowException(
airflow.exceptions.AirflowException: Job with id: ***_exportar_bq_para_gcs_csv_exportar_tabela_bq_gcs_2025_08_14T10_00_00_00_00_25a7e0156089b94962a331960db9c41f already exists and is in DONE state. If you want to force rerun it consider setting `force_rerun=True`.Or, if you want to reattach in this scenario add DONE to `reattach_states`
[2025-08-15T09:00:44.800-0300] {taskinstance.py:1206} INFO - Marking task as FAILED. dag_id=exportar_bq_para_gcs_csv, task_id=exportar_tabela_bq_gcs, run_id=scheduled__2025-08-14T10:00:00+00:00, execution_date=20250814T100000, start_date=20250815T120043, end_date=20250815T120044
[2025-08-15T09:00:44.809-0300] {standard_task_runner.py:110} ERROR - Failed to execute job 223 for task exportar_tabela_bq_gcs (Job with id: ***_exportar_bq_para_gcs_csv_exportar_tabela_bq_gcs_2025_08_14T10_00_00_00_00_25a7e0156089b94962a331960db9c41f already exists and is in DONE state. If you want to force rerun it consider setting `force_rerun=True`.Or, if you want to reattach in this scenario add DONE to `reattach_states`; 243)
[2025-08-15T09:00:44.820-0300] {local_task_job_runner.py:240} INFO - Task exited with return code 1
[2025-08-15T09:00:44.839-0300] {taskinstance.py:3498} INFO - 0 downstream tasks scheduled from follow-on schedule check
[2025-08-15T09:00:44.841-0300] {local_task_job_runner.py:222} INFO - ::endgroup::
