[2025-07-31T17:26:33.318-0300] {local_task_job_runner.py:120} INFO - ::group::Pre task execution logs
[2025-07-31T17:26:33.326-0300] {taskinstance.py:2076} INFO - Dependencies all met for dep_context=non-requeueable deps ti=<TaskInstance: exportar_bq_para_gcs_csv.baixar_csv_gcs manual__2025-07-31T20:26:00.855374+00:00 [queued]>
[2025-07-31T17:26:33.331-0300] {taskinstance.py:2076} INFO - Dependencies all met for dep_context=requeueable deps ti=<TaskInstance: exportar_bq_para_gcs_csv.baixar_csv_gcs manual__2025-07-31T20:26:00.855374+00:00 [queued]>
[2025-07-31T17:26:33.331-0300] {taskinstance.py:2306} INFO - Starting attempt 1 of 1
[2025-07-31T17:26:33.338-0300] {taskinstance.py:2330} INFO - Executing <Task(PythonOperator): baixar_csv_gcs> on 2025-07-31 20:26:00.855374+00:00
[2025-07-31T17:26:33.343-0300] {standard_task_runner.py:63} INFO - Started process 728 to run task
[2025-07-31T17:26:33.345-0300] {standard_task_runner.py:90} INFO - Running: ['***', 'tasks', 'run', 'exportar_bq_para_gcs_csv', 'baixar_csv_gcs', 'manual__2025-07-31T20:26:00.855374+00:00', '--job-id', '17', '--raw', '--subdir', 'DAGS_FOLDER/notas_ordem.py', '--cfg-path', '/tmp/tmp75etoant']
[2025-07-31T17:26:33.346-0300] {standard_task_runner.py:91} INFO - Job 17: Subtask baixar_csv_gcs
[2025-07-31T17:26:33.370-0300] {task_command.py:426} INFO - Running <TaskInstance: exportar_bq_para_gcs_csv.baixar_csv_gcs manual__2025-07-31T20:26:00.855374+00:00 [running]> on host 2778f3f60c85
[2025-07-31T17:26:33.414-0300] {taskinstance.py:2648} INFO - Exporting env vars: AIRFLOW_CTX_DAG_OWNER='***' AIRFLOW_CTX_DAG_ID='exportar_bq_para_gcs_csv' AIRFLOW_CTX_TASK_ID='baixar_csv_gcs' AIRFLOW_CTX_EXECUTION_DATE='2025-07-31T20:26:00.855374+00:00' AIRFLOW_CTX_TRY_NUMBER='1' AIRFLOW_CTX_DAG_RUN_ID='manual__2025-07-31T20:26:00.855374+00:00'
[2025-07-31T17:26:33.416-0300] {taskinstance.py:430} INFO - ::endgroup::
[2025-07-31T17:26:33.878-0300] {taskinstance.py:441} INFO - ::group::Post task execution logs
[2025-07-31T17:26:33.878-0300] {taskinstance.py:2905} ERROR - Task failed with exception
Traceback (most recent call last):
  File "/home/airflow/.local/lib/python3.11/site-packages/google/cloud/storage/blob.py", line 4362, in _prep_and_do_download
    self._do_download(
  File "/home/airflow/.local/lib/python3.11/site-packages/google/cloud/storage/blob.py", line 1017, in _do_download
    response = download.consume(transport, timeout=timeout)
               ^^^^^^^^^^^^^^^^^^^^^^^^^^^^^^^^^^^^^^^^^^^^
  File "/home/airflow/.local/lib/python3.11/site-packages/google/resumable_media/requests/download.py", line 237, in consume
    return _request_helpers.wait_and_retry(
           ^^^^^^^^^^^^^^^^^^^^^^^^^^^^^^^^
  File "/home/airflow/.local/lib/python3.11/site-packages/google/resumable_media/requests/_request_helpers.py", line 155, in wait_and_retry
    response = func()
               ^^^^^^
  File "/home/airflow/.local/lib/python3.11/site-packages/google/resumable_media/requests/download.py", line 219, in retriable_request
    self._process_response(result)
  File "/home/airflow/.local/lib/python3.11/site-packages/google/resumable_media/_download.py", line 188, in _process_response
    _helpers.require_status_code(
  File "/home/airflow/.local/lib/python3.11/site-packages/google/resumable_media/_helpers.py", line 108, in require_status_code
    raise common.InvalidResponse(
google.resumable_media.common.InvalidResponse: ('Request failed with status code', 404, 'Expected one of', 200, 206)

During handling of the above exception, another exception occurred:

Traceback (most recent call last):
  File "/home/airflow/.local/lib/python3.11/site-packages/airflow/models/taskinstance.py", line 465, in _execute_task
    result = _execute_callable(context=context, **execute_callable_kwargs)
             ^^^^^^^^^^^^^^^^^^^^^^^^^^^^^^^^^^^^^^^^^^^^^^^^^^^^^^^^^^^^^
  File "/home/airflow/.local/lib/python3.11/site-packages/airflow/models/taskinstance.py", line 432, in _execute_callable
    return execute_callable(context=context, **execute_callable_kwargs)
           ^^^^^^^^^^^^^^^^^^^^^^^^^^^^^^^^^^^^^^^^^^^^^^^^^^^^^^^^^^^^
  File "/home/airflow/.local/lib/python3.11/site-packages/airflow/models/baseoperator.py", line 400, in wrapper
    return func(self, *args, **kwargs)
           ^^^^^^^^^^^^^^^^^^^^^^^^^^^
  File "/home/airflow/.local/lib/python3.11/site-packages/airflow/operators/python.py", line 235, in execute
    return_value = self.execute_callable()
                   ^^^^^^^^^^^^^^^^^^^^^^^
  File "/home/airflow/.local/lib/python3.11/site-packages/airflow/operators/python.py", line 252, in execute_callable
    return self.python_callable(*self.op_args, **self.op_kwargs)
           ^^^^^^^^^^^^^^^^^^^^^^^^^^^^^^^^^^^^^^^^^^^^^^^^^^^^^
  File "/opt/airflow/dags/notas_ordem.py", line 12, in baixar_csv_para_csv_dir
    blob.download_to_filename('/opt/airflow/csv/nota_ordem.csv.gz')
  File "/home/airflow/.local/lib/python3.11/site-packages/google/cloud/storage/blob.py", line 1312, in download_to_filename
    self._handle_filename_and_download(
  File "/home/airflow/.local/lib/python3.11/site-packages/google/cloud/storage/blob.py", line 1188, in _handle_filename_and_download
    self._prep_and_do_download(
  File "/home/airflow/.local/lib/python3.11/site-packages/google/cloud/storage/blob.py", line 4375, in _prep_and_do_download
    _raise_from_invalid_response(exc)
  File "/home/airflow/.local/lib/python3.11/site-packages/google/cloud/storage/blob.py", line 4847, in _raise_from_invalid_response
    raise exceptions.from_http_status(response.status_code, message, response=response)
google.api_core.exceptions.NotFound: 404 GET https://storage.googleapis.com/download/storage/v1/b/airflow_vps/o/nota_ordem.csv.gz?alt=media: No such object: airflow_vps/nota_ordem.csv.gz: ('Request failed with status code', 404, 'Expected one of', <HTTPStatus.OK: 200>, <HTTPStatus.PARTIAL_CONTENT: 206>)
[2025-07-31T17:26:33.894-0300] {taskinstance.py:1206} INFO - Marking task as FAILED. dag_id=exportar_bq_para_gcs_csv, task_id=baixar_csv_gcs, run_id=manual__2025-07-31T20:26:00.855374+00:00, execution_date=20250731T202600, start_date=20250731T202633, end_date=20250731T202633
[2025-07-31T17:26:33.907-0300] {standard_task_runner.py:110} ERROR - Failed to execute job 17 for task baixar_csv_gcs (404 GET https://storage.googleapis.com/download/storage/v1/b/airflow_vps/o/nota_ordem.csv.gz?alt=media: No such object: airflow_vps/nota_ordem.csv.gz: ('Request failed with status code', 404, 'Expected one of', <HTTPStatus.OK: 200>, <HTTPStatus.PARTIAL_CONTENT: 206>); 728)
[2025-07-31T17:26:33.958-0300] {local_task_job_runner.py:240} INFO - Task exited with return code 1
[2025-07-31T17:26:33.982-0300] {taskinstance.py:3498} INFO - 0 downstream tasks scheduled from follow-on schedule check
[2025-07-31T17:26:33.985-0300] {local_task_job_runner.py:222} INFO - ::endgroup::
